<?xml version="1.0"?>
<!-- =================================================================================== -->
<!-- |    This document was autogenerated by xacro from arctos.xacro                   | -->
<!-- |    EDITING THIS FILE BY HAND IS NOT RECOMMENDED                                 | -->
<!-- =================================================================================== -->
<robot name="arctos">
  <material name="white">
    <color rgba="1.0 1.0 1.0 1.000" />
  </material>
  <material name="black">
    <color rgba="0.0 0.0 0.0 1.0" />
  </material>
  <link name="world" />
  <link name="base_link">
    <visual>
      <origin rpy="0 0 0" xyz="0 0 0" />
      <geometry>
        <mesh filename="package://arctos_description/meshes/base_link.stl" scale="0.001 0.001 0.001" />
      </geometry>
      <material name="white" />
    </visual>
    <collision>
      <origin rpy="0 0 0" xyz="0 0 0" />
      <geometry>
        <mesh filename="package://arctos_description/meshes/base_link.stl" scale="0.001 0.001 0.001" />
      </geometry>
    </collision>
    <inertial>
      <origin rpy="0 0 0" xyz="0.0009375030874740357 0.047087016508753216 0.06663230338123677" />
      <mass value="7.598577592821282" />
      <inertia ixx="0.063328" ixy="-0.000434" ixz="0.000108" iyy="0.03095" iyz="0.001366"
        izz="0.072371" />
    </inertial>
  </link>
  <link name="Link_1_1">
    <visual>
      <origin rpy="0 0 0" xyz="0.0 -0.000529 -0.111" />
      <geometry>
        <mesh filename="package://arctos_description/meshes/Link_1_1.stl" scale="0.001 0.001 0.001" />
      </geometry>
      <material name="white" />
    </visual>
    <collision>
      <origin rpy="0 0 0" xyz="0.0 -0.000529 -0.111" />
      <geometry>
        <mesh filename="package://arctos_description/meshes/Link_1_1.stl" scale="0.001 0.001 0.001" />
      </geometry>
    </collision>
    <inertial>
      <origin rpy="0 0 0" xyz="0.0022188890353287776 -0.004863444449475237 0.08546835509394825" />
      <mass value="10.394711633971145" />
      <inertia ixx="0.061139" ixy="0.00017" ixz="-0.00148" iyy="0.073854" iyz="0.003835"
        izz="0.05669" />
    </inertial>
  </link>
  <link name="Link_2_1">
    <visual>
      <origin rpy="0 0 0" xyz="0.05713 0.020356 -0.289378" />
      <geometry>
        <mesh filename="package://arctos_description/meshes/Link_2_1.stl" scale="0.001 0.001 0.001" />
      </geometry>
      <material name="white" />
    </visual>
    <collision>
      <origin rpy="0 0 0" xyz="0.05713 0.020356 -0.289378" />
      <geometry>
        <mesh filename="package://arctos_description/meshes/Link_2_1.stl" scale="0.001 0.001 0.001" />
      </geometry>
    </collision>
    <inertial>
      <origin rpy="0 0 0" xyz="0.055314283466519745 0.010843565259072822 0.11412354328486207" />
      <mass value="11.558090086674309" />
      <inertia ixx="0.128567" ixy="3e-06" ixz="0.001539" iyy="0.14463" iyz="-0.003293"
        izz="0.044463" />
    </inertial>
  </link>
  <link name="Link_3_1">
    <visual>
      <origin rpy="0 0 0" xyz="-0.043 0.019045 -0.550385" />
      <geometry>
        <mesh filename="package://arctos_description/meshes/Link_3_1.stl" scale="0.001 0.001 0.001" />
      </geometry>
      <material name="white" />
    </visual>
    <collision>
      <origin rpy="0 0 0" xyz="-0.043 0.019045 -0.550385" />
      <geometry>
        <mesh filename="package://arctos_description/meshes/Link_3_1.stl" scale="0.001 0.001 0.001" />
      </geometry>
    </collision>
    <inertial>
      <origin rpy="0 0 0" xyz="-0.04178369242643258 -0.03913025368943244 0.01221763827191602" />
      <mass value="3.601405589552794" />
      <inertia ixx="0.012497" ixy="-3.6e-05" ixz="-8.1e-05" iyy="0.006916" iyz="0.001536"
        izz="0.011789" />
    </inertial>
  </link>
  <link name="Link_4_1">
    <visual>
      <origin rpy="0 0 0" xyz="-1e-06 0.15874 -0.57209" />
      <geometry>
        <mesh filename="package://arctos_description/meshes/Link_4_1.stl" scale="0.001 0.001 0.001" />
      </geometry>
      <material name="white" />
    </visual>
    <collision>
      <origin rpy="0 0 0" xyz="-1e-06 0.15874 -0.57209" />
      <geometry>
        <mesh filename="package://arctos_description/meshes/Link_4_1.stl" scale="0.001 0.001 0.001" />
      </geometry>
    </collision>
    <inertial>
      <origin rpy="0 0 0" xyz="0.00021104999825562586 -0.06028834880207104 -0.0005408226217131773" />
      <mass value="3.7852887653107565" />
      <inertia ixx="0.011624" ixy="-9e-06" ixz="4e-06" iyy="0.011491" iyz="-7.1e-05" izz="0.017363" />
    </inertial>
  </link>
  <link name="Link_5_1">
    <visual>
      <origin rpy="0 0 0" xyz="0.039011 0.279927 -0.570316" />
      <geometry>
        <mesh filename="package://arctos_description/meshes/Link_5_1.stl" scale="0.001 0.001 0.001" />
      </geometry>
      <material name="white" />
    </visual>
    <collision>
      <origin rpy="0 0 0" xyz="0.039011 0.279927 -0.570316" />
      <geometry>
        <mesh filename="package://arctos_description/meshes/Link_5_1.stl" scale="0.001 0.001 0.001" />
      </geometry>
    </collision>
    <inertial>
      <origin rpy="0 0 0" xyz="0.0397291414278933 -0.012662394123331089 0.0007929187272999183" />
      <mass value="0.8319811655030993" />
      <inertia ixx="0.000732" ixy="-1.2e-05" ixz="5e-06" iyy="0.000958" iyz="-5e-06" izz="0.000907" />
    </inertial>
  </link>
  <link name="Link_6_1">
    <visual>
      <origin rpy="0 0 0" xyz="-0.000193 0.313762 -0.570316" />
      <geometry>
        <mesh filename="package://arctos_description/meshes/Link_6_1.stl" scale="0.001 0.001 0.001" />
      </geometry>
      <material name="white" />
    </visual>
    <collision>
      <origin rpy="0 0 0" xyz="-0.000193 0.313762 -0.570316" />
      <geometry>
        <mesh filename="package://arctos_description/meshes/Link_6_1.stl" scale="0.001 0.001 0.001" />
      </geometry>
    </collision>
    <inertial>
      <origin rpy="0 0 0" xyz="6.567e-08 -0.00304 -3.032e-07" />
      <mass value="0.10343478090890781" />
      <inertia ixx="5.2e-05" ixy="-0.0" ixz="0.0" iyy="0.000103" iyz="0.0" izz="5.2e-05" />
    </inertial>
  </link>
  <joint name="base_joint" type="fixed">
    <parent link="world" />
    <child link="base_link" />
    <origin rpy="0 0 0" xyz="0 0 0" />
  </joint>
  <joint name="X_joint" type="continuous">
    <parent link="base_link" />
    <child link="Link_1_1" />
    <origin rpy="0 0 0" xyz="0.0 0.000529 0.111" />
    <axis xyz="0 0 1" />
    <limit effort="100.0" lower="-6.283185307179586" upper="6.283185307179586" velocity="100.0" />
  </joint>
  <joint name="Y_joint" type="continuous">
    <parent link="Link_1_1" />
    <child link="Link_2_1" />
    <origin rpy="0 0 0" xyz="-0.05713 -0.020885 0.178378" />
    <axis xyz="1 0 0" />
    <limit effort="100.0" lower="-6.283185307179586" upper="6.283185307179586" velocity="100.0" />
  </joint>
  <joint name="Z_joint" type="continuous">
    <parent link="Link_2_1" />
    <child link="Link_3_1" />
    <origin rpy="0 0 0" xyz="0.10013 0.001311 0.261007" />
    <axis xyz="-1 0 0" />
    <limit effort="100.0" lower="-3.141592653589793" upper="3.141592653589793" velocity="100.0" />
  </joint>
  <joint name="A_joint" type="continuous">
    <parent link="Link_3_1" />
    <child link="Link_4_1" />
    <origin rpy="0 0 0" xyz="-0.042999 -0.139695 0.021705" />
    <axis xyz="0 1 0" />
    <limit effort="100.0" lower="-6.283185307179586" upper="6.283185307179586" velocity="100.0" />
  </joint>
  <joint name="B_joint" type="continuous">
    <parent link="Link_4_1" />
    <child link="Link_5_1" />
    <origin rpy="0 0 0" xyz="-0.039012 -0.121187 -0.001774" />
    <axis xyz="-1 0 0" />
    <limit effort="100.0" lower="-6.283185307179586" upper="6.283185307179586" velocity="100.0" />
  </joint>
  <joint name="C_joint" type="continuous">
    <parent link="Link_5_1" />
    <child link="Link_6_1" />
    <origin rpy="0 0 0" xyz="0.039204 -0.033835 0.0" />
    <axis xyz="0 1 0" />
    <limit effort="100.0" lower="-6.283185307179586" upper="6.283185307179586" velocity="100.0" />
  </joint>
  <link name="Gripper_1">
    <visual>
      <origin rpy="0 0 0" xyz="-0.000193 0.319847 -0.570316" />
      <geometry>
        <mesh filename="package://arctos_description/meshes/Gripper_1.stl" scale="0.001 0.001 0.001" />
      </geometry>
      <material name="white" />
    </visual>
    <collision>
      <origin rpy="0 0 0" xyz="-0.000193 0.319847 -0.570316" />
      <geometry>
        <mesh filename="package://arctos_description/meshes/Gripper_1.stl" scale="0.001 0.001 0.001" />
      </geometry>
    </collision>
    <inertial>
      <origin rpy="0 0 0" xyz="0.0036112727264542635 -0.014760653808445767 -0.00103677815369696" />
      <mass value="0.5810486809925093" />
      <inertia ixx="0.000385" ixy="1e-05" ixz="3e-06" iyy="0.000495" iyz="-2e-06" izz="0.000263" />
    </inertial>
  </link>
  <link name="Left_jaw_1">
    <visual>
      <origin rpy="0 0 0" xyz="-0.007934 0.359845 -0.599867" />
      <geometry>
        <mesh filename="package://arctos_description/meshes/Left_jaw_1.stl"
          scale="0.001 0.001 0.001" />
      </geometry>
      <material name="white" />
    </visual>
    <collision>
      <origin rpy="0 0 0" xyz="-0.007934 0.359845 -0.599867" />
      <geometry>
        <mesh filename="package://arctos_description/meshes/Left_jaw_1.stl"
          scale="0.001 0.001 0.001" />
      </geometry>
    </collision>
    <inertial>
      <origin rpy="0 0 0" xyz="-0.011142702480351952 -0.009692440309284511 -0.009385792627785827" />
      <mass value="0.07369602565859415" />
      <inertia ixx="1.1e-05" ixy="2e-06" ixz="-0.0" iyy="6e-06" iyz="-0.0" izz="1.4e-05" />
    </inertial>
  </link>
  <link name="Right_jaw_1">
    <visual>
      <origin rpy="0 0 0" xyz="-0.007934 0.359845 -0.539867" />
      <geometry>
        <mesh filename="package://arctos_description/meshes/Right_jaw_1.stl"
          scale="0.001 0.001 0.001" />
      </geometry>
      <material name="white" />
    </visual>
    <collision>
      <origin rpy="0 0 0" xyz="-0.007934 0.359845 -0.539867" />
      <geometry>
        <mesh filename="package://arctos_description/meshes/Right_jaw_1.stl"
          scale="0.001 0.001 0.001" />
      </geometry>
    </collision>
    <inertial>
      <origin rpy="0 0 0" xyz="-0.008289104952972526 -0.009768535307719373 0.009395511902715814" />
      <mass value="0.07312902168719511" />
      <inertia ixx="1.1e-05" ixy="-1e-06" ixz="-1e-06" iyy="6e-06" iyz="0.0" izz="1.4e-05" />
    </inertial>
  </link>
  <joint name="Gripper_joint" type="fixed">
    <parent link="Link_6_1" />
    <child link="Gripper_1" />
    <origin rpy="0 0 0" xyz="0.0 -0.006085 0.0" />
    <axis xyz="0 0 0" />
    <limit effort="0.0" lower="0.0" upper="0.0" velocity="0.0" />
  </joint>
  <joint name="Left_jaw_joint" type="prismatic">
    <parent link="Gripper_1" />
    <child link="Left_jaw_1" />
    <origin rpy="0 0 0" xyz="0.007741 -0.039998 0.029551" />
    <axis xyz="0 0 -1" />
    <limit effort="100.0" lower="0.0" upper="0.015" velocity="100.0" />
    <dynamics damping="0.0" friction="0.0" />
  </joint>
  <joint name="Right_jaw_joint" type="prismatic">
    <parent link="Gripper_1" />
    <child link="Right_jaw_1" />
    <origin rpy="0 0 0" xyz="0.007741 -0.039998 -0.030449" />
    <axis xyz="0 0 1" />
    <limit effort="100.0" lower="0.0" upper="0.015" velocity="100.0" />
    <mimic joint="Left_jaw_joint" multiplier="1.0" offset="0.0" />
    <dynamics damping="0.0" friction="0.0" />
  </joint>
  <ros2_control name="arctos_hardware_interface" type="system">
    <hardware>
      <plugin>arctos_control/ArctosSerialHardwareInterface</plugin>
      <param name="serial_port">/dev/ttyUSB0</param>
      <param name="baud_rate">115200</param>
      <param name="feed_rate">800</param>
      <param name="abs_motion">True</param>
    </hardware>
    <joint name="X_joint">
      <command_interface name="position">
        <param name="min">-6.283185307179586</param>
        <param name="max">6.283185307179586</param>
      </command_interface>
      <state_interface name="position">
        <param name="initial_value">0.0</param>
      </state_interface>
    </joint>
    <joint name="Y_joint">
      <command_interface name="position">
        <param name="min">-6.283185307179586</param>
        <param name="max">6.283185307179586</param>
      </command_interface>
      <state_interface name="position">
        <param name="initial_value">0.0</param>
      </state_interface>
    </joint>
    <joint name="Z_joint">
      <command_interface name="position">
        <param name="min">-3.141592653589793</param>
        <param name="max">3.141592653589793</param>
      </command_interface>
      <state_interface name="position">
        <param name="initial_value">0.0</param>
      </state_interface>
    </joint>
    <joint name="A_joint">
      <command_interface name="position">
        <param name="min">-6.283185307179586</param>
        <param name="max">6.283185307179586</param>
      </command_interface>
      <state_interface name="position">
        <param name="initial_value">0.0</param>
      </state_interface>
    </joint>
    <joint name="B_joint">
      <command_interface name="position">
        <param name="min">-6.283185307179586</param>
        <param name="max">6.283185307179586</param>
      </command_interface>
      <state_interface name="position">
        <param name="initial_value">0.0</param>
      </state_interface>
    </joint>
    <joint name="C_joint">
      <command_interface name="position">
        <param name="min">-6.283185307179586</param>
        <param name="max">6.283185307179586</param>
      </command_interface>
      <state_interface name="position">
        <param name="initial_value">0.0</param>
      </state_interface>
    </joint>
    <joint name="Left_jaw_joint">
      <command_interface name="position">
        <param name="min">0.0</param>
        <param name="max">0.015</param>
      </command_interface>
      <state_interface name="position">
        <param name="initial_value">0.0</param>
      </state_interface>
    </joint>
    <!-- <joint name="Right_jaw_joint">
        <param name="mimic">Left_jaw_joint</param>
        <param name="multiplier">1.0</param>
        <param name="offset">0.0</param>
        <state_interface name="position">
          <param name="initial_value">0.0</param>
        </state_interface>
      </joint> -->
  </ros2_control>
</robot>